Traceback (most recent call last):
  File "/home/tyler_andrew_scott/anaconda3/lib/python3.5/site-packages/selenium/webdriver/common/service.py", line 74, in start
    stdout=self.log_file, stderr=self.log_file)
  File "/home/tyler_andrew_scott/anaconda3/lib/python3.5/subprocess.py", line 947, in __init__
    restore_signals, start_new_session)
  File "/home/tyler_andrew_scott/anaconda3/lib/python3.5/subprocess.py", line 1551, in _execute_child
    raise child_exception_type(errno_num, err_msg)
FileNotFoundError: [Errno 2] No such file or directory: 'phantomjs'

During handling of the above exception, another exception occurred:

Traceback (most recent call last):
  File "scrape_tceq_all.py", line 20, in <module>
    driver = webdriver.PhantomJS()
  File "/home/tyler_andrew_scott/anaconda3/lib/python3.5/site-packages/selenium/webdriver/phantomjs/webdriver.py", line 52, in __init__
    self.service.start()
  File "/home/tyler_andrew_scott/anaconda3/lib/python3.5/site-packages/selenium/webdriver/common/service.py", line 81, in start
    os.path.basename(self.path), self.start_error_message)
selenium.common.exceptions.WebDriverException: Message: 'phantomjs' executable needs to be in PATH. 

Exception ignored in: <bound method Service.__del__ of <selenium.webdriver.phantomjs.service.Service object at 0x7f7fc97280f0>>
Traceback (most recent call last):
  File "/home/tyler_andrew_scott/anaconda3/lib/python3.5/site-packages/selenium/webdriver/common/service.py", line 173, in __del__
    self.stop()
  File "/home/tyler_andrew_scott/anaconda3/lib/python3.5/site-packages/selenium/webdriver/common/service.py", line 145, in stop
    if self.process is None:
AttributeError: 'Service' object has no attribute 'process'
